Workbook
Name dayspr: 'Raw data'!$B$4:$AL$60
Name dayspo: 'Raw data'!$K$4:$AL$60

Sheet Days Sesion
A1: NO | B1: TAHAPAN | C1: PROSES PENGADAAN JASA | D1: MEDIA | E1: QT | F1: SATUAN | G1: TAKE TIME (MENIT) | H1: HARI | I1: JML ORANG | J1: TOTAL per Tahapan (Menit) | K1: Satuan Hari | P1: Keterangan | Q1: Menit | R1: Days | S1: Persentase setiap bagian
A2: 1 | B2: Disposisi PR | C2: VP Menerima PR | D2: SIPS | E2: 56 | F2: Item PR | G2: 10 | H2: =G2/1440 -> 0.0069444444 | I2: 1 | J2: =sum(G2:G5) -> 100 | K2: =J2/(60*24) -> 0.069444444 | L2: Paling banyak makan waktu (karena Manual) | P2: =B2 -> Disposisi PR | Q2: =J2 -> 100 | R2: =K2 -> 0.069444444 | S2: =R2/$R$12 -> 0.0020151134
A3: 2 | C3: VP Disposisi ke AVP | D3: SIPS | E3: 56 | F3: Item PR | G3: 20 | H3: =G3/1440 -> 0.013888889 | I3: 1 | L3: Paling lama | P3: =B6 -> Pembuatan Proposal Tender | Q3: =J6 -> 40 | R3: =K6 -> 0.027777778 | S3: =R3/$R$12 -> 0.00080604534
A4: 3 | C4: AVP Disposisi ke Buyer | D4: SIPS | E4: 56 | F4: Item PR | G4: 10 | H4: =G4/1440 -> 0.0069444444 | I4: 1 | P4: =B11 -> Pembuatan DUR & Approval | Q4: =J11 -> 8960 | R4: =K11 -> 6.2222222 | S4: =R4/$R$12 -> 0.18055416
A5: 4 | C5: Replikasi PR ke Eproc | D5: Eproc | E5: 56 | F5: Item PR | G5: 60 | H5: =G5/1440 -> 0.041666667 | I5: 1 | P5: =B19 -> Aanwijzing | Q5: =J19 -> 4370 | R5: =K19 -> 3.0347222 | S5: =R5/$R$12 -> 0.088060453
A6: 5 | B6: Pembuatan Proposal Tender | C6: Judul dan Referensi Tender | D6: Eproc | E6: 56 | F6: Item PR | G6: 5 | H6: =G6/1440 -> 0.0034722222 | I6: 1 | J6: =sum(G6:G10) -> 40 | K6: =J6/(60*24) -> 0.027777778 | P6: =B23 -> Penawaran Rekanan | Q6: =J23 -> 10125 | R6: =K23 -> 7.03125 | S6: =R6/$R$12 -> 0.20403023
A7: 6 | C7: Upload Dokumen Pengadaan | D7: Eproc | E7: 56 | F7: Item PR | G7: 10 | H7: =G7/1440 -> 0.0069444444 | I7: 1 | P7: =B27 -> Evaluasi Teknis | Q7: =J27 -> 6585 | R7: =K27 -> 4.5729167 | S7: =R7/$R$12 -> 0.13269521
A8: 7 | C8: Mengisi Detail Tender | D8: Eproc | E8: 56 | F8: Item PR | G8: 10 | H8: =G8/1440 -> 0.0069444444 | I8: 1 | P8: =B53 -> Negosiasi | Q8: =J53 -> 1560 | R8: =K53 -> 1.0833333 | S8: =R8/$R$12 -> 0.031435768
A9: 8 | C9: Mengisi Jawdal Tender | D9: Eproc | E9: 56 | F9: Item PR | G9: 5 | H9: =G9/1440 -> 0.0034722222 | I9: 1 | P9: =B62 -> Usulan Pemenang | Q9: =J62 -> 8940 | R9: =K62 -> 6.2083333 | S9: =R9/$R$12 -> 0.18015113
A10: 9 | C10: Mengisi Persyaratan Tender | D10: Eproc | E10: 56 | F10: Item PR | G10: 10 | H10: =G10/1440 -> 0.0069444444 | I10: 1 | P10: =B68 -> Purchase Order (PO) | Q10: =J68 -> 8940 | R10: =K68 -> 6.2083333 | S10: =R10/$R$12 -> 0.18015113
A11: 10 | B11: Pembuatan DUR & Approval | C11: Pembuatan DUR di Eproc | D11: Eproc | E11: 56 | F11: Item PR | G11: 20 | H11: =G11/1440 -> 0.013888889 | I11: 1 | J11: =sum(G11:G18) -> 8960 | K11: =J11/(60*24) -> 6.2222222 | P11: =B75 -> Kirim PO | Q11: =J75 -> 5 | R11: =K75 -> 0.0034722222
A12: 11 | C12: Download File DUR dari Eproc | D12: Eproc | E12: 56 | F12: Item PR | G12: 5 | H12: =G12/1440 -> 0.0034722222 | I12: 1 | P12: Total | Q12: =sum(Q2:Q11) -> 49625 | R12: =sum(R2:R11) -> 34.461806
A13: 12 | C13: Upload File DUR ke SIPS | D13: SIPS | E13: 56 | F13: Item PR | G13: 5 | H13: =G13/1440 -> 0.0034722222 | I13: 1
A14: 13 | C14: Mengisi Detail Tender dan DUR | D14: SIPS | E14: 56 | F14: Item PR | G14: 10 | H14: =G14/1440 -> 0.0069444444 | I14: 1
A15: 14 | C15: Approval AVP | D15: Eproc & SIPS | E15: 56 | F15: Item PR | G15: 40 | H15: =G15/1440 -> 0.027777778 | I15: 1
A16: 15 | C16: Approval VP | D16: Eproc & SIPS | E16: 56 | F16: Item PR | G16: 180 | H16: =G16/1440 -> 0.125 | I16: 1
A17: 16 | C17: Approval SVP | D17: Eproc & SIPS | E17: 56 | F17: Item PR | G17: 1500 | H17: =G17/1440 -> 1.0416667 | I17: 1
A18: 17 | C18: Approval Direksi | D18: Eproc & SIPS | E18: 56 | F18: Item PR | G18: 7200 | H18: =G18/1440 -> 5 | I18: 1
A19: 18 | B19: Aanwijzing | C19: Membuat Undangan Aanwijzing | D19: SIPS | E19: 56 | F19: Item PR | G19: 10 | H19: =G19/1440 -> 0.0069444444 | I19: 1 | J19: =sum(G19:G22) -> 4370 | K19: =J19/(60*24) -> 3.0347222
A20: 19 | C20: Pelaksanaan Aanwijzing | D20: Zoom | E20: 56 | F20: Item PR | G20: 4320 | H20: =G20/1440 -> 3 | I20: 1
A21: 20 | C21: Membuat BA Aanwijzing | D21: Word | E21: 56 | F21: Item PR | G21: 30 | H21: =G21/1440 -> 0.020833333 | I21: 1
A22: 21 | C22: Mengirim BA Aanwijzing | D22: Email | E22: 56 | F22: Item PR | G22: 10 | H22: =G22/1440 -> 0.0069444444 | I22: 1
A23: 22 | B23: Penawaran Rekanan | C23: Rekanan Upload Dokumen | D23: Eproc | E23: 56 | F23: Item PR | G23: 10080 | H23: =G23/1440 -> 7 | I23: 1 | J23: =sum(G23:G26) -> 10125 | K23: =J23/(60*24) -> 7.03125
A24: 23 | C24: Buyer Menerima Dokumen | D24: Eproc | E24: 56 | F24: Item PR | G24: 10 | H24: =G24/1440 -> 0.0069444444 | I24: 1
A25: 24 | C25: Buyer Download Dokumen | D25: Eproc | E25: 56 | F25: Item PR | G25: 15 | H25: =G25/1440 -> 0.010416667 | I25: 1
A26: 25 | C26: Buyer Upload Dokumen | D26: SIPS | E26: 56 | F26: Item PR | G26: 20 | H26: =G26/1440 -> 0.013888889 | I26: 1
A27: 26 | B27: Evaluasi Teknis | C27: Buyer Mengirim Dokumen ke PPBJ untuk Evaluasi Teknis | D27: SIPS | E27: 56 | F27: Item PR | G27: 20 | H27: =G27/1440 -> 0.013888889 | I27: 1 | J27: =sum(G27:G52) -> 6585 | K27: =J27/(60*24) -> 4.5729167
A28: 27 | C28: Approval AVP Daan Jasa | D28: SIPS | E28: 56 | F28: Item PR | G28: 10 | H28: =G28/1440 -> 0.0069444444 | I28: 1
A29: 28 | C29: Approval VP Daan Jasa | D29: SIPS | E29: 56 | F29: Item PR | G29: 120 | H29: =G29/1440 -> 0.083333333 | I29: 1
A30: 29 | C30: VP PPBJ Menerima Dokumen | D30: SIPS | E30: 56 | F30: Item PR | G30: 10 | H30: =G30/1440 -> 0.0069444444 | I30: 1
A31: 30 | C31: VP PPBJ Disposisi ke AVP PPBJ Jasa | D31: SIPS | E31: 56 | F31: Item PR | G31: 20 | H31: =G31/1440 -> 0.013888889 | I31: 1
A32: 31 | C32: AVP PPBJ Jasa Disposisi ke Staf | D32: SIPS | E32: 56 | F32: Item PR | G32: 20 | H32: =G32/1440 -> 0.013888889 | I32: 1
A33: 32 | C33: Staf PPBJ Menerima Dokumen Penawaran | D33: SIPS | E33: 56 | F33: Item PR | G33: 10 | H33: =G33/1440 -> 0.0069444444 | I33: 1
A34: 33 | C34: Staf PPBJ Melakukan Evaluasi dan Kirim User | D34: SIPS | E34: 56 | F34: Item PR | G34: 60 | H34: =G34/1440 -> 0.041666667 | I34: 1
A35: 34 | C35: Approval AVP PPBJ Jasa | D35: SIPS | E35: 56 | F35: Item PR | G35: 10 | H35: =G35/1440 -> 0.0069444444 | I35: 1
A36: 35 | C36: Approval VP PPBJ | D36: SIPS | E36: 56 | F36: Item PR | G36: 120 | H36: =G36/1440 -> 0.083333333 | I36: 1
A37: 36 | C37: VP User Menerima Evaluasi | D37: SIPS | E37: 56 | F37: Item PR | G37: 10 | H37: =G37/1440 -> 0.0069444444 | I37: 1
A38: 37 | C38: VP User Disposisi ke AVP User | D38: SIPS | E38: 56 | F38: Item PR | G38: 10 | H38: =G38/1440 -> 0.0069444444 | I38: 1
A39: 38 | C39: AVP User Disposisi ke Staf | D39: SIPS | E39: 56 | F39: Item PR | G39: 10 | H39: =G39/1440 -> 0.0069444444 | I39: 1
... A52: 51 | C52: AVP Disposisi ke Buyer | D52: SIPS | E52: 56 | F52: Item PR | G52: 10 | H52: =G52/1440 -> 0.0069444444 | I52: 1
...

Sheet VANVA (Current)
A1: NO | B1: TAHAPAN | C1: PROSES PENGADAAN JASA | D1: MEDIA | E1: SINGLE PLATFORM | F1: VA/NVA | G1: KETERANGAN | I1: QT | J1: SATUAN | K1: TAKE TIME (MENIT) | L1: HARI | M1: JML ORANG | N1: TOTAL per Tahapan (Menit) | O1: Satuan Hari | T1: Keterangan | U1: Menit | V1: Days | X1: Persentase setiap bagian
A2: 1 | B2: Disposisi PR | C2: VP Menerima PR | D2: SIPS | E2: Eproc V3 | F2: VA | I2: 56 | J2: Item PR | K2: 10 | L2: =K2/1440 -> 0.0069444444 | M2: 1 | N2: =sum(K2:K5) -> 100 | O2: =N2/(60*24) -> 0.069444444 | P2: Paling banyak makan waktu (karena Manual) | T2: =B2 -> Disposisi PR | U2: =N2 -> 100 | V2: =O2 -> 0.069444444 | X2: =V2/$V$12 -> 0.0020151134
A3: 2 | C3: VP Disposisi ke AVP | D3: SIPS | E3: Eproc V3 | F3: VA | I3: 56 | J3: Item PR | K3: 20 | L3: =K3/1440 -> 0.013888889 | M3: 1 | P3: Paling lama | T3: =B6 -> Pembuatan Proposal Tender | U3: =N6 -> 40 | V3: =O6 -> 0.027777778 | X3: =V3/$V$12 -> 0.00080604534
A4: 3 | C4: AVP Disposisi ke Buyer | D4: SIPS | E4: Eproc V3 | F4: VA | I4: 56 | J4: Item PR | K4: 10 | L4: =K4/1440 -> 0.0069444444 | M4: 1 | T4: =B11 -> Pembuatan DUR & Approval | U4: =N11 -> 8960 | V4: =O11 -> 6.2222222 | X4: =V4/$V$12 -> 0.18055416
A5: 4 | C5: Replikasi PR ke Eproc | D5: Eproc | F5: NVA | I5: 56 | J5: Item PR | K5: 60 | L5: =K5/1440 -> 0.041666667 | M5: 1 | T5: =B19 -> Aanwijzing | U5: =N19 -> 4370 | V5: =O19 -> 3.0347222 | X5: =V5/$V$12 -> 0.088060453
A6: 5 | B6: Pembuatan Proposal Tender | C6: Judul dan Referensi Tender | D6: Eproc | E6: Eproc V3 | F6: VA | I6: 56 | J6: Item PR | K6: 5 | L6: =K6/1440 -> 0.0034722222 | M6: 1 | N6: =sum(K6:K10) -> 40 | O6: =N6/(60*24) -> 0.027777778 | T6: =B23 -> Penawaran Rekanan | U6: =N23 -> 10125 | V6: =O23 -> 7.03125 | X6: =V6/$V$12 -> 0.20403023
A7: 6 | C7: Upload Dokumen Pengadaan | D7: Eproc | E7: Eproc V3 | F7: VA | I7: 56 | J7: Item PR | K7: 10 | L7: =K7/1440 -> 0.0069444444 | M7: 1 | T7: =B27 -> Evaluasi Teknis | U7: =N27 -> 6585 | V7: =O27 -> 4.5729167 | X7: =V7/$V$12 -> 0.13269521
A8: 7 | C8: Mengisi Detail Tender | D8: Eproc | E8: Eproc V3 | F8: VA | I8: 56 | J8: Item PR | K8: 10 | L8: =K8/1440 -> 0.0069444444 | M8: 1 | T8: =B53 -> Negosiasi | U8: =N53 -> 1560 | V8: =O53 -> 1.0833333 | X8: =V8/$V$12 -> 0.031435768
A9: 8 | C9: Mengisi Jawdal Tender | D9: Eproc | E9: Eproc V3 | F9: VA | I9: 56 | J9: Item PR | K9: 5 | L9: =K9/1440 -> 0.0034722222 | M9: 1 | T9: =B62 -> Usulan Pemenang | U9: =N62 -> 8940 | V9: =O62 -> 6.2083333 | X9: =V9/$V$12 -> 0.18015113
A10: 9 | C10: Mengisi Persyaratan Tender | D10: Eproc | E10: Eproc V3 | F10: VA | I10: 56 | J10: Item PR | K10: 10 | L10: =K10/1440 -> 0.0069444444 | M10: 1 | T10: =B68 -> Purchase Order (PO) | U10: =N68 -> 8940 | V10: =O68 -> 6.2083333 | X10: =V10/$V$12 -> 0.18015113
A11: 10 | B11: Pembuatan DUR & Approval | C11: Pembuatan DUR di Eproc | D11: Eproc | E11: Eproc V3 | F11: VA | I11: 56 | J11: Item PR | K11: 20 | L11: =K11/1440 -> 0.013888889 | M11: 1 | N11: =sum(K11:K18) -> 8960 | O11: =N11/(60*24) -> 6.2222222 | T11: =B75 -> Kirim PO | U11: =N75 -> 5 | V11: =O75 -> 0.0034722222
A12: 11 | C12: Download File DUR dari Eproc | D12: Eproc | F12: NVA | I12: 56 | J12: Item PR | K12: 5 | L12: =K12/1440 -> 0.0034722222 | M12: 1 | T12: Total | U12: =sum(U2:U11) -> 49625 | V12: =sum(V2:V11) -> 34.461806
A13: 12 | C13: Upload File DUR ke SIPS | D13: SIPS | F13: NVA | I13: 56 | J13: Item PR | K13: 5 | L13: =K13/1440 -> 0.0034722222 | M13: 1
A14: 13 | C14: Mengisi Detail Tender dan DUR | D14: SIPS | F14: NVA | I14: 56 | J14: Item PR | K14: 10 | L14: =K14/1440 -> 0.0069444444 | M14: 1
A15: 14 | C15: Approval AVP | D15: Eproc & SIPS | E15: Eproc V3 | F15: VA | I15: 56 | J15: Item PR | K15: 40 | L15: =K15/1440 -> 0.027777778 | M15: 1
A16: 15 | C16: Approval VP | D16: Eproc & SIPS | E16: Eproc V3 | F16: VA | I16: 56 | J16: Item PR | K16: 180 | L16: =K16/1440 -> 0.125 | M16: 1
A17: 16 | C17: Approval SVP | D17: Eproc & SIPS | E17: Eproc V3 | F17: VA | I17: 56 | J17: Item PR | K17: 1500 | L17: =K17/1440 -> 1.0416667 | M17: 1
A18: 17 | C18: Approval Direksi | D18: Eproc & SIPS | E18: Eproc V3 | F18: VA | I18: 56 | J18: Item PR | K18: 7200 | L18: =K18/1440 -> 5 | M18: 1
A19: 18 | B19: Aanwijzing | C19: Membuat Undangan Aanwijzing | D19: SIPS | E19: Eproc V3 | F19: VA | I19: 56 | J19: Item PR | K19: 10 | L19: =K19/1440 -> 0.0069444444 | M19: 1 | N19: =sum(K19:K22) -> 4370 | O19: =N19/(60*24) -> 3.0347222
A20: 19 | C20: Pelaksanaan Aanwijzing | D20: Zoom | E20: Zoom | F20: VA | I20: 56 | J20: Item PR | K20: 4320 | L20: =K20/1440 -> 3 | M20: 1
A21: 20 | C21: Membuat BA Aanwijzing | D21: Word | E21: Word | F21: VA | I21: 56 | J21: Item PR | K21: 30 | L21: =K21/1440 -> 0.020833333 | M21: 1
A22: 21 | C22: Mengirim BA Aanwijzing | D22: Email | E22: Email | F22: VA | I22: 56 | J22: Item PR | K22: 10 | L22: =K22/1440 -> 0.0069444444 | M22: 1
A23: 22 | B23: Penawaran Rekanan | C23: Rekanan Upload Dokumen | D23: Eproc | F23: VA | I23: 56 | J23: Item PR | K23: 10080 | L23: =K23/1440 -> 7 | M23: 1 | N23: =sum(K23:K26) -> 10125 | O23: =N23/(60*24) -> 7.03125
A24: 23 | C24: Buyer Menerima Dokumen | D24: Eproc | F24: VA | I24: 56 | J24: Item PR | K24: 10 | L24: =K24/1440 -> 0.0069444444 | M24: 1
A25: 24 | C25: Buyer Download Dokumen | D25: Eproc | F25: NVA | I25: 56 | J25: Item PR | K25: 15 | L25: =K25/1440 -> 0.010416667 | M25: 1
A26: 25 | C26: Buyer Upload Dokumen | D26: SIPS | F26: NVA | I26: 56 | J26: Item PR | K26: 20 | L26: =K26/1440 -> 0.013888889 | M26: 1
A27: 26 | B27: Evaluasi Teknis | C27: Buyer Mengirim Dokumen ke PPBJ untuk Evaluasi Teknis | D27: SIPS | F27: VA | I27: 56 | J27: Item PR | K27: 20 | L27: =K27/1440 -> 0.013888889 | M27: 1 | N27: =sum(K27:K52) -> 6585 | O27: =N27/(60*24) -> 4.5729167
A28: 27 | C28: Approval AVP Daan Jasa | D28: SIPS | F28: VA | I28: 56 | J28: Item PR | K28: 10 | L28: =K28/1440 -> 0.0069444444 | M28: 1
A29: 28 | C29: Approval VP Daan Jasa | D29: SIPS | F29: VA | I29: 56 | J29: Item PR | K29: 120 | L29: =K29/1440 -> 0.083333333 | M29: 1
A30: 29 | C30: VP PPBJ Menerima Dokumen | D30: SIPS | F30: NVA | I30: 56 | J30: Item PR | K30: 10 | L30: =K30/1440 -> 0.0069444444 | M30: 1
A31: 30 | C31: VP PPBJ Disposisi ke AVP PPBJ Jasa | D31: SIPS | F31: NVA | I31: 56 | J31: Item PR | K31: 20 | L31: =K31/1440 -> 0.013888889 | M31: 1
A32: 31 | C32: AVP PPBJ Jasa Disposisi ke Staf | D32: SIPS | F32: NVA | I32: 56 | J32: Item PR | K32: 20 | L32: =K32/1440 -> 0.013888889 | M32: 1
A33: 32 | C33: Staf PPBJ Menerima Dokumen Penawaran | D33: SIPS | F33: NVA | I33: 56 | J33: Item PR | K33: 10 | L33: =K33/1440 -> 0.0069444444 | M33: 1
A34: 33 | C34: Staf PPBJ Melakukan Evaluasi dan Kirim User | D34: SIPS | F34: VA | I34: 56 | J34: Item PR | K34: 60 | L34: =K34/1440 -> 0.041666667 | M34: 1
A35: 34 | C35: Approval AVP PPBJ Jasa | D35: SIPS | F35: NVA | I35: 56 | J35: Item PR | K35: 10 | L35: =K35/1440 -> 0.0069444444 | M35: 1
A36: 35 | C36: Approval VP PPBJ | D36: SIPS | F36: NVA | I36: 56 | J36: Item PR | K36: 120 | L36: =K36/1440 -> 0.083333333 | M36: 1
A37: 36 | C37: VP User Menerima Evaluasi | D37: SIPS | F37: VA | I37: 56 | J37: Item PR | K37: 10 | L37: =K37/1440 -> 0.0069444444 | M37: 1
A38: 37 | C38: VP User Disposisi ke AVP User | D38: SIPS | F38: VA | I38: 56 | J38: Item PR | K38: 10 | L38: =K38/1440 -> 0.0069444444 | M38: 1
A39: 38 | C39: AVP User Disposisi ke Staf | D39: SIPS | F39: VA | I39: 56 | J39: Item PR | K39: 10 | L39: =K39/1440 -> 0.0069444444 | M39: 1
... A52: 51 | C52: AVP Disposisi ke Buyer | D52: SIPS | F52: VA | I52: 56 | J52: Item PR | K52: 10 | L52: =K52/1440 -> 0.0069444444 | M52: 1
...

Sheet VANVA (Future)
A1: NO | B1: TAHAPAN | C1: PROSES PENGADAAN JASA | D1: MEDIA | E1: SINGLE PLATFORM | F1: VA/NVA | G1: QT | H1: SATUAN | I1: TAKE TIME (MENIT) | J1: HARI | K1: JML ORANG | L1: TOTAL per Tahapan (Menit) | M1: Satuan Hari | R1: Keterangan | S1: Menit | T1: Days | U1: Persentase setiap bagian
A2: 1 | B2: Disposisi PR | C2: VP Menerima PR | D2: SIPS | E2: Eproc V3 | F2: VA | G2: 56 | H2: Item PR | I2: 10 | J2: =I2/1440 -> 0.0069444444 | K2: 1 | L2: =sum(I2:I4) -> 40 | M2: =L2/(60*24) -> 0.027777778 | N2: Paling banyak makan waktu (karena Manual) | R2: =B2 -> Disposisi PR | S2: =L2 -> 40 | T2: =M2 -> 0.027777778 | U2: =T2/$T$12 -> 0.00081674324
A3: 2 | C3: VP Disposisi ke AVP | D3: SIPS | E3: Eproc V3 | F3: VA | G3: 56 | H3: Item PR | I3: 20 | J3: =I3/1440 -> 0.013888889 | K3: 1 | N3: Paling lama | R3: =B5 -> Pembuatan Proposal Tender | S3: =L5 -> 40 | T3: =M5 -> 0.027777778 | U3: =T3/$T$12 -> 0.00081674324
A4: 3 | C4: AVP Disposisi ke Buyer | D4: SIPS | E4: Eproc V3 | F4: VA | G4: 56 | H4: Item PR | I4: 10 | J4: =I4/1440 -> 0.0069444444 | K4: 1 | R4: =B10 -> Pembuatan DUR & Approval | S4: =L10 -> 8940 | T4: =M10 -> 6.2083333 | U4: =T4/$T$12 -> 0.18254211
A5: 4 | B5: Pembuatan Proposal Tender | C5: Judul dan Referensi Tender | D5: Eproc | E5: Eproc V3 | F5: VA | G5: 56 | H5: Item PR | I5: 5 | J5: =I5/1440 -> 0.0034722222 | K5: 1 | L5: =sum(I5:I9) -> 40 | M5: =L5/(60*24) -> 0.027777778 | R5: =B15 -> Aanwijzing | S5: =L15 -> 4370 | T5: =M15 -> 3.0347222 | U5: =T5/$T$12 -> 0.089229199
A6: 5 | C6: Upload Dokumen Pengadaan | D6: Eproc | E6: Eproc V3 | F6: VA | G6: 56 | H6: Item PR | I6: 10 | J6: =I6/1440 -> 0.0069444444 | K6: 1 | R6: =B19 -> Penawaran Rekanan | S6: =L19 -> 10090 | T6: =M19 -> 7.0069444 | U6: =T6/$T$12 -> 0.20602348
A7: 6 | C7: Mengisi Detail Tender | D7: Eproc | E7: Eproc V3 | F7: VA | G7: 56 | H7: Item PR | I7: 10 | J7: =I7/1440 -> 0.0069444444 | K7: 1 | R7: =B21 -> Evaluasi Teknis | S7: =L21 -> 6120 | T7: =M21 -> 4.25 | U7: =T7/$T$12 -> 0.12496172
A8: 7 | C8: Mengisi Jawdal Tender | D8: Eproc | E8: Eproc V3 | F8: VA | G8: 56 | H8: Item PR | I8: 5 | J8: =I8/1440 -> 0.0034722222 | K8: 1 | R8: =B34 -> Negosiasi | S8: =L34 -> 1510 | T8: =M34 -> 1.0486111 | U8: =T8/$T$12 -> 0.030832057
A9: 8 | C9: Mengisi Persyaratan Tender | D9: Eproc | E9: Eproc V3 | F9: VA | G9: 56 | H9: Item PR | I9: 10 | J9: =I9/1440 -> 0.0069444444 | K9: 1 | R9: =B40 -> Usulan Pemenang | S9: =L45 -> 8930 | T9: =M45 -> 6.2013889 | U9: =T9/$T$12 -> 0.18233793
A10: 9 | B10: Pembuatan DUR & Approval | C10: Pembuatan DUR di Eproc | D10: Eproc | E10: Eproc V3 | F10: VA | G10: 56 | H10: Item PR | I10: 20 | J10: =I10/1440 -> 0.013888889 | K10: 1 | L10: =sum(I10:I14) -> 8940 | M10: =L10/(60*24) -> 6.2083333 | R10: =B45 -> Purchase Order (PO) | S10: =L45 -> 8930 | T10: =M45 -> 6.2013889 | U10: =T10/$T$12 -> 0.18233793
A11: 10 | C11: Approval AVP | D11: Eproc & SIPS | E11: Eproc V3 | F11: VA | G11: 56 | H11: Item PR | I11: 40 | J11: =I11/1440 -> 0.027777778 | K11: 1 | R11: =B50 -> Kirim PO | S11: =L50 -> 5 | T11: =M50 -> 0.0034722222 | U11: =T11/$T$12 -> 0.0001020929
A12: 11 | C12: Approval VP | D12: Eproc & SIPS | E12: Eproc V3 | F12: VA | G12: 56 | H12: Item PR | I12: 180 | J12: =I12/1440 -> 0.125 | K12: 1 | R12: Total | S12: =sum(S2:S11) -> 48975 | T12: =sum(T2:T11) -> 34.010417
A13: 12 | C13: Approval SVP | D13: Eproc & SIPS | E13: Eproc V3 | F13: VA | G13: 56 | H13: Item PR | I13: 1500 | J13: =I13/1440 -> 1.0416667 | K13: 1
A14: 13 | C14: Approval Direksi | D14: Eproc & SIPS | E14: Eproc V3 | F14: VA | G14: 56 | H14: Item PR | I14: 7200 | J14: =I14/1440 -> 5 | K14: 1
A15: 14 | B15: Aanwijzing | C15: Membuat Undangan Aanwijzing | D15: SIPS | E15: Eproc V3 | F15: VA | G15: 56 | H15: Item PR | I15: 10 | J15: =I15/1440 -> 0.0069444444 | K15: 1 | L15: =sum(I15:I18) -> 4370 | M15: =L15/(60*24) -> 3.0347222
A16: 15 | C16: Pelaksanaan Aanwijzing | D16: Zoom | E16: Zoom | F16: VA | G16: 56 | H16: Item PR | I16: 4320 | J16: =I16/1440 -> 3 | K16: 1
A17: 16 | C17: Membuat BA Aanwijzing | D17: Word | E17: Word | F17: VA | G17: 56 | H17: Item PR | I17: 30 | J17: =I17/1440 -> 0.020833333 | K17: 1
A18: 17 | C18: Mengirim BA Aanwijzing | D18: Email | E18: Email | F18: VA | G18: 56 | H18: Item PR | I18: 10 | J18: =I18/1440 -> 0.0069444444 | K18: 1
A19: 18 | B19: Penawaran Rekanan | C19: Rekanan Upload Dokumen | D19: Eproc | F19: VA | G19: 56 | H19: Item PR | I19: 10080 | J19: =I19/1440 -> 7 | K19: 1 | L19: =sum(I19:I20) -> 10090 | M19: =L19/(60*24) -> 7.0069444
A20: 19 | C20: Buyer Menerima Dokumen | D20: Eproc | F20: VA | G20: 56 | H20: Item PR | I20: 10 | J20: =I20/1440 -> 0.0069444444 | K20: 1
A21: 20 | B21: Evaluasi Teknis | C21: Buyer Mengirim Dokumen ke User untuk Evaluasi Teknis | D21: SIPS | F21: VA | G21: 56 | H21: Item PR | I21: 20 | J21: =I21/1440 -> 0.013888889 | K21: 1 | L21: =sum(I21:I33) -> 6120 | M21: =L21/(60*24) -> 4.25
A22: 21 | C22: Approval AVP Daan Jasa | D22: SIPS | F22: NVA | G22: 56 | H22: Item PR | I22: 10 | J22: =I22/1440 -> 0.0069444444 | K22: 1
A23: 22 | C23: Approval VP Daan Jasa | D23: SIPS | F23: NVA | G23: 56 | H23: Item PR | I23: 120 | J23: =I23/1440 -> 0.083333333 | K23: 1
A24: 23 | C24: VP User Menerima Evaluasi | D24: SIPS | F24: NVA | G24: 56 | H24: Item PR | I24: 10 | J24: =I24/1440 -> 0.0069444444 | K24: 1
A25: 24 | C25: VP User Disposisi ke AVP User | D25: SIPS | F25: NVA | G25: 56 | H25: Item PR | I25: 10 | J25: =I25/1440 -> 0.0069444444 | K25: 1
A26: 25 | C26: AVP User Disposisi ke Staf | D26: SIPS | F26: NVA | G26: 56 | H26: Item PR | I26: 10 | J26: =I26/1440 -> 0.0069444444 | K26: 1
A27: 26 | C27: Staf Melakukan Evaluasi Teknis | D27: SIPS | F27: VA | G27: 56 | H27: Item PR | I27: 5760 | J27: =I27/1440 -> 4 | K27: 1
A28: 27 | C28: Staf Mengirimkan Hasil Evaluasi Teknis ke Daan Jasa | D28: SIPS | F28: VA | G28: 56 | H28: Item PR | I28: 10 | J28: =I28/1440 -> 0.0069444444 | K28: 1
A29: 28 | C29: Approval AVP User | D29: SIPS | F29: NVA | G29: 56 | H29: Item PR | I29: 10 | J29: =I29/1440 -> 0.0069444444 | K29: 1
A30: 29 | C30: Approval VP User | D30: SIPS | F30: NVA | G30: 56 | H30: Item PR | I30: 120 | J30: =I30/1440 -> 0.083333333 | K30: 1
A31: 30 | C31: VP Daan Jasa Menerima Hasil Evaluasi | D31: SIPS | F31: NVA | G31: 56 | H31: Item PR | I31: 10 | J31: =I31/1440 -> 0.0069444444 | K31: 1
A32: 31 | C32: VP Daan Jasa Disposisi ke AVP | D32: SIPS | F32: NVA | G32: 56 | H32: Item PR | I32: 20 | J32: =I32/1440 -> 0.013888889 | K32: 1
A33: 32 | C33: AVP Disposisi ke Buyer | D33: SIPS | F33: NVA | G33: 56 | H33: Item PR | I33: 10 | J33: =I33/1440 -> 0.0069444444 | K33: 1
A34: 33 | B34: Negosiasi | C34: Buyer Melanjutkan Proses Evaluasi untuk Rekanan yang Lolos Tahap Selanjutnya | D34: Eproc | F34: VA | G34: 56 | H34: Item PR | I34: 30 | J34: =I34/1440 -> 0.020833333 | K34: 1 | L34: =sum(I34:I39) -> 1510 | M34: =L34/(60*24) -> 1.0486111
A35: 34 | C35: Buyer Mengajukan Approval Negosiasi ke AVP | D35: SIPS | F35: VA | G35: 56 | H35: Item PR | I35: 10 | J35: =I35/1440 -> 0.0069444444 | K35: 1
A36: 35 | C36: Approval AVP untuk Proses Negosiasi | D36: SIPS | F36: VA | G36: 56 | H36: Item PR | I36: 10 | J36: =I36/1440 -> 0.0069444444 | K36: 1
A37: 36 | C37: Buyer Membuat Jadwal Negosiasi di Epoc | D37: Eproc | F37: VA | G37: 56 | H37: Item PR | I37: 10 | J37: =I37/1440 -> 0.0069444444 | K37: 1
A38: 37 | C38: Proses Negosiasi dengan Rekanan | D38: Eproc | F38: VA | G38: 56 | H38: Item PR | I38: 1440 | J38: =I38/1440 -> 1 | K38: 1
A39: 38 | C39: Approval AVP Hasil Negosiasi | D39: SIPS | F39: VA | G39: 56 | H39: Item PR | I39: 10 | J39: =I39/1440 -> 0.0069444444 | K39: 1
A40: 39 | B40: Usulan Pemenang | C40: Pengajuan Usulan Pemenang | D40: Eproc | F40: VA | G40: 56 | H40: Item PR | I40: 10 | J40: =I40/1440 -> 0.0069444444 | K40: 1 | L40: =sum(I40:I44) -> 8930 | M40: =L40/(60*24) -> 6.2013889
...

Sheet VANVA (Future) Versi 2
A1: NO | B1: TAHAPAN | C1: PROSES PENGADAAN JASA | D1: MEDIA | E1: SINGLE PLATFORM | F1: VA/NVA | G1: QT | H1: SATUAN | I1: TAKT TIME (MENIT) | K1: HARI | L1: JML ORANG | M1: TOTAL per Tahapan (Menit) | N1: Satuan Hari | S1: Keterangan | T1: Menit | U1: Days | V1: Persentase setiap bagian
A2: 1 | B2: Disposisi PR | C2: VP Menerima PR | D2: SIPS | E2: Eproc V3 | F2: VA | G2: 56 | H2: Item PR | I2: 10 | K2: =I2/1440 -> 0.0069444444 | L2: 1 | M2: =sum(I2:I4) -> 40 | N2: =M2/(60*24) -> 0.027777778 | O2: Paling banyak makan waktu (karena Manual) | S2: =B2 -> Disposisi PR | T2: =M2 -> 40 | U2: =N2 -> 0.027777778 | V2: =U2/$U$12 -> 0.00082009226
A3: 2 | C3: VP Disposisi ke AVP | D3: SIPS | E3: Eproc V3 | F3: VA | G3: 56 | H3: Item PR | I3: 20 | K3: =I3/1440 -> 0.013888889 | L3: 1 | O3: Paling lama | S3: =B5 -> Pembuatan Proposal Tender | T3: =M5 -> 40 | U3: =N5 -> 0.027777778 | V3: =U3/$U$12 -> 0.00082009226
A4: 3 | C4: AVP Disposisi ke Buyer | D4: SIPS | E4: Eproc V3 | F4: VA | G4: 56 | H4: Item PR | I4: 10 | K4: =I4/1440 -> 0.0069444444 | L4: 1 | S4: =B10 -> Pembuatan DUR & Approval | T4: =M10 -> 8940 | U4: =N10 -> 6.2083333 | V4: =U4/$U$12 -> 0.18329062
A5: 4 | B5: Pembuatan Proposal Tender | C5: Judul dan Referensi Tender | D5: Eproc | E5: Eproc V3 | F5: VA | G5: 56 | H5: Item PR | I5: 5 | K5: =I5/1440 -> 0.0034722222 | L5: 1 | M5: =sum(I5:I9) -> 40 | N5: =M5/(60*24) -> 0.027777778 | S5: =B15 -> Aanwijzing | T5: =M15 -> 4370 | U5: =N15 -> 3.0347222 | V5: =U5/$U$12 -> 0.089595079
A6: 5 | C6: Upload Dokumen Pengadaan | D6: Eproc | E6: Eproc V3 | F6: VA | G6: 56 | H6: Item PR | I6: 10 | K6: =I6/1440 -> 0.0069444444 | L6: 1 | S6: =B19 -> Penawaran Rekanan | T6: =M19 -> 10090 | U6: =N19 -> 7.0069444 | V6: =U6/$U$12 -> 0.20686827
A7: 6 | C7: Mengisi Detail Tender | D7: Eproc | E7: Eproc V3 | F7: VA | G7: 56 | H7: Item PR | I7: 10 | K7: =I7/1440 -> 0.0069444444 | L7: 1 | S7: =B21 -> Evaluasi Teknis | T7: =M21 -> 5920 | U7: =N21 -> 4.1111111 | V7: =U7/$U$12 -> 0.12137365
A8: 7 | C8: Mengisi Jawdal Tender | D8: Eproc | E8: Eproc V3 | F8: VA | G8: 56 | H8: Item PR | I8: 5 | K8: =I8/1440 -> 0.0034722222 | L8: 1 | S8: =B26 -> Negosiasi | T8: =M27 -> 1510 | U8: =N27 -> 1.0486111 | V8: =U8/$U$12 -> 0.030958483
A9: 8 | C9: Mengisi Persyaratan Tender | D9: Eproc | E9: Eproc V3 | F9: VA | G9: 56 | H9: Item PR | I9: 10 | K9: =I9/1440 -> 0.0069444444 | L9: 1 | S9: =B33 -> Usulan Pemenang | T9: =M33 -> 8930 | U9: =N33 -> 6.2013889 | V9: =U9/$U$12 -> 0.1830856
A10: 9 | B10: Pembuatan DUR & Approval | C10: Pembuatan DUR di Eproc | D10: Eproc | E10: Eproc V3 | F10: VA | G10: 56 | H10: Item PR | I10: 20 | K10: =I10/1440 -> 0.013888889 | L10: 1 | M10: =sum(I10:I14) -> 8940 | N10: =M10/(60*24) -> 6.2083333 | S10: =B38 -> Purchase Order (PO) | T10: =M38 -> 8930 | U10: =N38 -> 6.2013889 | V10: =U10/$U$12 -> 0.1830856
A11: 10 | C11: Approval AVP | D11: Eproc & SIPS | E11: Eproc V3 | F11: VA | G11: 56 | H11: Item PR | I11: 40 | K11: =I11/1440 -> 0.027777778 | L11: 1 | S11: =B43 -> Kirim PO | T11: =M43 -> 5 | U11: =N43 -> 0.0034722222 | V11: =U11/$U$12 -> 0.00010251153
A12: 11 | C12: Approval VP | D12: Eproc & SIPS | E12: Eproc V3 | F12: VA | G12: 56 | H12: Item PR | I12: 180 | K12: =I12/1440 -> 0.125 | L12: 1 | T12: =sum(T2:T11) -> 48775 | U12: =sum(U2:U11) -> 33.871528
A13: 12 | C13: Approval SVP | D13: Eproc & SIPS | E13: Eproc V3 | F13: VA | G13: 56 | H13: Item PR | I13: 1500 | K13: =I13/1440 -> 1.0416667 | L13: 1
A14: 13 | C14: Approval Direksi | D14: Eproc & SIPS | E14: Eproc V3 | F14: VA | G14: 56 | H14: Item PR | I14: 7200 | K14: =I14/1440 -> 5 | L14: 1
A15: 14 | B15: Aanwijzing | C15: Membuat Undangan Aanwijzing | D15: SIPS | E15: Eproc V3 | F15: VA | G15: 56 | H15: Item PR | I15: 10 | K15: =I15/1440 -> 0.0069444444 | L15: 1 | M15: =sum(I15:I18) -> 4370 | N15: =M15/(60*24) -> 3.0347222
A16: 15 | C16: Pelaksanaan Aanwijzing | D16: Zoom | E16: Zoom | F16: VA | G16: 56 | H16: Item PR | I16: 4320 | K16: =I16/1440 -> 3 | L16: 1
A17: 16 | C17: Membuat BA Aanwijzing | D17: Word | E17: Word | F17: VA | G17: 56 | H17: Item PR | I17: 30 | K17: =I17/1440 -> 0.020833333 | L17: 1
A18: 17 | C18: Mengirim BA Aanwijzing | D18: Email | E18: Email | F18: VA | G18: 56 | H18: Item PR | I18: 10 | K18: =I18/1440 -> 0.0069444444 | L18: 1
A19: 18 | B19: Penawaran Rekanan | C19: Rekanan Upload Dokumen | D19: Eproc | E19: Eproc V3 | F19: VA | G19: 56 | H19: Item PR | I19: 10080 | K19: =I19/1440 -> 7 | L19: 1 | M19: =sum(I19:I20) -> 10090 | N19: =M19/(60*24) -> 7.0069444
A20: 19 | C20: Buyer Menerima Dokumen | D20: Eproc | E20: Eproc V3 | F20: VA | G20: 56 | H20: Item PR | I20: 10 | K20: =I20/1440 -> 0.0069444444 | L20: 1
A21: 20 | B21: Evaluasi Teknis | C21: Buyer Mengirim Dokumen ke User untuk Evaluasi Teknis | D21: SIPS | E21: Eproc V3 | F21: VA | G21: 56 | H21: Item PR | I21: 20 | K21: =I21/1440 -> 0.013888889 | L21: 1 | M21: =sum(I21:I25) -> 5920 | N21: =M21/(60*24) -> 4.1111111
A22: 21 | C22: Staf Melakukan Evaluasi Teknis | D22: SIPS | E22: Eproc V3 | F22: VA | G22: 56 | H22: Item PR | I22: 5760 | K22: =I22/1440 -> 4 | L22: 1
A23: 22 | C23: Staf Mengirimkan Hasil Evaluasi Teknis ke Daan Jasa | D23: SIPS | E23: Eproc V3 | F23: VA | G23: 56 | H23: Item PR | I23: 10 | K23: =I23/1440 -> 0.0069444444 | L23: 1
A24: 23 | C24: Approval AVP User | D24: SIPS | E24: Eproc V3 | F24: VA | G24: 56 | H24: Item PR | I24: 10 | K24: =I24/1440 -> 0.0069444444 | L24: 1
A25: 24 | C25: Approval VP User | D25: SIPS | E25: Eproc V3 | F25: VA | G25: 56 | H25: Item PR | I25: 120 | K25: =I25/1440 -> 0.083333333 | L25: 1
A26: 25 | B26: Negosiasi | C26: Buyer Menerima Hasil Evaluasi Teknis | E26: Eproc V3 | F26: VA | I26: 5
A27: 26 | C27: Buyer Melanjutkan Proses Evaluasi untuk Rekanan yang Lolos Tahap Selanjutnya | D27: Eproc | E27: Eproc V3 | F27: VA | G27: 56 | H27: Item PR | I27: 30 | K27: =I27/1440 -> 0.020833333 | L27: 1 | M27: =sum(I27:I32) -> 1510 | N27: =M27/(60*24) -> 1.0486111
A28: 27 | C28: Buyer Mengajukan Approval Negosiasi ke AVP | D28: SIPS | E28: Eproc V3 | F28: VA | G28: 56 | H28: Item PR | I28: 10 | K28: =I28/1440 -> 0.0069444444 | L28: 1
A29: 28 | C29: Approval AVP untuk Proses Negosiasi | D29: SIPS | E29: Eproc V3 | F29: VA | G29: 56 | H29: Item PR | I29: 10 | K29: =I29/1440 -> 0.0069444444 | L29: 1
A30: 29 | C30: Buyer Membuat Jadwal Negosiasi di Epoc | D30: Eproc | E30: Eproc V3 | F30: VA | G30: 56 | H30: Item PR | I30: 10 | K30: =I30/1440 -> 0.0069444444 | L30: 1
A31: 30 | C31: Proses Negosiasi dengan Rekanan | D31: Eproc | E31: Eproc V3 | F31: VA | G31: 56 | H31: Item PR | I31: 1440 | K31: =I31/1440 -> 1 | L31: 1
A32: 31 | C32: Approval AVP Hasil Negosiasi | D32: SIPS | E32: Eproc V3 | F32: VA | G32: 56 | H32: Item PR | I32: 10 | K32: =I32/1440 -> 0.0069444444 | L32: 1
A33: 32 | B33: Usulan Pemenang | C33: Pengajuan Usulan Pemenang | D33: Eproc | E33: Eproc V3 | F33: VA | G33: 56 | H33: Item PR | I33: 10 | K33: =I33/1440 -> 0.0069444444 | L33: 1 | M33: =sum(I33:I37) -> 8930 | N33: =M33/(60*24) -> 6.2013889
A34: 33 | C34: Approval AVP | D34: Eproc & SIPS | E34: Eproc V3 | F34: VA | G34: 56 | H34: Item PR | I34: 40 | K34: =I34/1440 -> 0.027777778 | L34: 1
A35: 34 | C35: Approval VP | D35: Eproc & SIPS | E35: Eproc V3 | F35: VA | G35: 56 | H35: Item PR | I35: 180 | K35: =I35/1440 -> 0.125 | L35: 1
A36: 35 | C36: Approval SVP | D36: Eproc & SIPS | E36: Eproc V3 | F36: VA | G36: 56 | H36: Item PR | I36: 1500 | K36: =I36/1440 -> 1.0416667 | L36: 1
A37: 36 | C37: Approval Direksi | D37: Eproc & SIPS | E37: Eproc V3 | F37: VA | G37: 56 | H37: Item PR | I37: 7200 | K37: =I37/1440 -> 5 | L37: 1
A38: 37 | B38: Purchase Order (PO) | C38: Create PO | D38: SAP | E38: Eproc V3 | F38: VA | G38: 56 | H38: Item PO | I38: 10 | K38: =I38/1440 -> 0.0069444444 | L38: 1 | M38: =sum(I38:I42) -> 8930 | N38: =M38/(60*24) -> 6.2013889
A39: 38 | C39: Approval AVP | D39: SIPS | E39: Eproc V3 | F39: VA | G39: 56 | H39: Item PO | I39: 40 | K39: =I39/1440 -> 0.027777778 | L39: 1
A40: 39 | C40: Approval VP | D40: SIPS | E40: Eproc V3 | F40: VA | G40: 56 | H40: Item PO | I40: 180 | K40: =I40/1440 -> 0.125 | L40: 1
...

Sheet Rata-rata
A1: Nik | B1: Nama | C1: PR | D1: Item Of | E1: Status | F1: Material Number | G1: Short text | H1: Purchasing Group | I1: Requisition Date | J1: Release Date | K1: Tanggal Disposisi Buyer | L1: Disposisi PR - Proposal Tender | M1: Proposal Tender - DUR & Approval | N1: DUR & Approval - Aanwijzing | O1: Aanwijzing - Penawaran Rekanan | P1: Penawaran Rekanan - Evaluasi Teknis | Q1: Evaluasi Teknis - Negosiasi | R1: Negosiasi - Usulan Pemenang | S1: Usulan Pemenang - PO | T1: Total SLA | U1: Total SLA - Realisasi days | V1: Tanggal PO | W1: Requisitioner | X1: PR-PO | Y1: Total SLA - Realisasi days | Z1: No PO | AA1: Prioritas | AB1: Outline Aggrement | AC1: Kontrak/Non kontrak | AD1: Standard SLA | AE1: Realisasi SLA | AF1: Days SLA | AG1: Nilai SLA | AH1: Nomor MR/SR | AI1: Nilai MR/SR | AJ1: OE PR | AK1: Nilai Item PO | AL1: Persentase PO/SR atau PO/MR | AM1: Nilai Persentase PO/SR atau PO/MR
L2: 7 | N2: 8 | P2: 12 | Q2: 16 | S2: 19
A3: 2166575 | B3: Deisza Tarramif Thahull | C3: 2200097480 | D3: 10 | E3: Closed | F3: S37Z | G3: [SA2]Jasa Major Inspection generator | H3: B37 | I3: 25/10/2024 | K3: 23/01/2025 | L3: =Value(left(vlookup(Z3,dayspo,7,0),1)) -> 1 | M3: =roundup(Y3*'Days Sesion'!$S$2,0) -> 1 | N3: =roundup(Y3*'Days Sesion'!$S$3,0) -> 1 | O3: =roundup(Y3*'Days Sesion'!$S$5,0) -> 2 | P3: =Value(left(vlookup(Z3,dayspo,7,0),1)) -> 1 | Q3: =value(left(vlookup(Z3,dayspo,8,0),1)) -> 6 | R3: =roundup(Y3*'Days Sesion'!$S$8,0) -> 1 | S3: =(value(left(vlookup(Z3,dayspo,19,0),1))) -> 4 | T3: =roundup(sum(L3:S3),0) -> 17 | U3: =T3-AF3 -> 6 | V3: 13/02/2025 | W3: TA3SA225 | X3: 13 Hari | Y3: =value(left(X3,2)) -> 13 | Z3: 5100134537 | AA3: TA | AC3: Non Agreement | AD3: 15 Hari | AE3: 11 Hari | AF3: =value(left(AE3,2)) -> 11 | AG3: 1 | AH3: 3630/E26000/SR/SIPS/2024 | AI3: Rp 963.845.578 | AJ3: Rp 951.290.153 | AK3: Rp. 945.000.000 | AL3: 99.34 % | AM3: 1
A4: 2166575 | B4: Deisza Tarramif Thahull | C4: 2200098910 | D4: 10 | E4: Closed | F4: S41C | G4: Perbaikan Alat & Mesin Bengkel Pabrik 3 | H4: B41 | I4: 27/12/2024 | J4: 22/01/2025 | K4: 45659 | L4: =Value(left(vlookup(Z4,dayspo,7,0),1)) -> 2 | M4: =roundup(Y4*'Days Sesion'!$S$2,0) -> 1 | N4: =roundup(Y4*'Days Sesion'!$S$3,0) -> 1 | O4: =roundup(Y4*'Days Sesion'!$S$5,0) -> 1 | P4: =Value(left(vlookup(Z4,dayspo,7,0),1)) -> 2 | Q4: =value(left(vlookup(Z4,dayspo,8,0),1)) -> 4 | R4: =roundup(Y4*'Days Sesion'!$S$8,0) -> 1 | S4: =(value(left(vlookup(Z4,dayspo,19,0),1))) -> 2 | T4: =roundup(sum(L4:S4),0) -> 14 | U4: =T4-AF4 -> 6 | V4: 15/01/2025 | W4: IREPC24 | X4: 9 Hari | Y4: =value(left(X4,2)) -> 9 | Z4: 5100133759 | AA4: Normal | AC4: Non Agreement | AD4: 40 Hari | AE4: 8 Hari | AF4: =value(left(AE4,2)) -> 8 | AG4: 1 | AH4: 3934/E2D000/SR/SIPS/2024 | AI4: Rp 225.155.000 | AJ4: Rp 225.155.000 | AK4: Rp. 220.500.000 | AL4: 97.93 % | AM4: 1
A5: 2166575 | B5: Deisza Tarramif Thahull | C5: 2200098928 | D5: 10 | E5: Closed | F5: S37H | G5: (AMMONIA IA) Jasa Perbaikan Rotor 103 JH | H5: B37 | I5: 45689 | J5: 45689 | K5: 45663 | L5: =Value(left(vlookup(Z5,dayspo,7,0),1)) -> 0 | M5: =roundup(Y5*'Days Sesion'!$S$2,0) -> 1 | N5: =roundup(Y5*'Days Sesion'!$S$3,0) -> 1 | O5: =roundup(Y5*'Days Sesion'!$S$5,0) -> 1 | P5: =Value(left(vlookup(Z5,dayspo,7,0),1)) -> 0 | Q5: =value(left(vlookup(Z5,dayspo,8,0),1)) -> 3 | R5: =roundup(Y5*'Days Sesion'!$S$8,0) -> 1 | S5: =(value(left(vlookup(Z5,dayspo,19,0),1))) -> 3 | T5: =roundup(sum(L5:S5),0) -> 10 | U5: =T5-AF5 -> 4 | V5: 18/01/2025 | W5: IREPC25 | X5: 10 Hari | Y5: =value(left(X5,2)) -> 10 | Z5: 5100133854 | AA5: Normal | AC5: Non Agreement | AD5: 40 Hari | AE5: 6 Hari | AF5: =value(left(AE5,2)) -> 6 | AG5: 1 | AH5: 3932/E2D000/SR/SIPS/2024 | AI5: Rp 601.250.000 | AJ5: Rp 583.045.775 | AK5: Rp. 531.180.000 | AL5: 91.1 % | AM5: 1
A6: 2166575 | B6: Deisza Tarramif Thahull | C6: 2200099021 | D6: 10 | E6: Closed | F6: S37Z | G6: Rebabbit Journal Bearing P21101 | H6: B37 | I6: 45689 | J6: 45689 | K6: 45664 | L6: =Value(left(vlookup(Z6,dayspo,7,0),1)) -> 1 | M6: =roundup(Y6*'Days Sesion'!$S$2,0) -> 1 | N6: =roundup(Y6*'Days Sesion'!$S$3,0) -> 1 | O6: =roundup(Y6*'Days Sesion'!$S$5,0) -> 1 | P6: =Value(left(vlookup(Z6,dayspo,7,0),1)) -> 1 | Q6: =value(left(vlookup(Z6,dayspo,8,0),1)) -> 5 | R6: =roundup(Y6*'Days Sesion'!$S$8,0) -> 1 | S6: =(value(left(vlookup(Z6,dayspo,19,0),1))) -> 1 | T6: =roundup(sum(L6:S6),0) -> 12 | U6: =T6-AF6 -> 5 | V6: 16/01/2025 | W6: IREPC24 | X6: 7 Hari | Y6: =value(left(X6,2)) -> 7 | Z6: 5100133816 | AA6: Normal | AC6: Non Agreement | AD6: 40 Hari | AE6: 7 Hari | AF6: =value(left(AE6,2)) -> 7 | AG6: 1 | AH6: 3938/E2D000/SR/SIPS/2024 | AI6: Rp 46.500.000 | AJ6: Rp 46.500.000 | AK6: Rp. 46.000.000 | AL6: 98.92 % | AM6: 1
A7: 2166575 | B7: Deisza Tarramif Thahull | C7: 2200099022 | D7: 10 | E7: Closed | F7: S50Z | G7: Monitoring Pemeliharaan ElevatorPrilling | H7: B50 | I7: 45689 | J7: 23/05/2025 | K7: 45664 | L7: =Value(left(vlookup(Z7,dayspo,7,0),1)) -> 1 | M7: =roundup(Y7*'Days Sesion'!$S$2,0) -> 1 | N7: =roundup(Y7*'Days Sesion'!$S$3,0) -> 1 | O7: =roundup(Y7*'Days Sesion'!$S$5,0) -> 2 | P7: =Value(left(vlookup(Z7,dayspo,7,0),1)) -> 1 | Q7: =value(left(vlookup(Z7,dayspo,8,0),1)) -> 4 | R7: =roundup(Y7*'Days Sesion'!$S$8,0) -> 1 | S7: =(value(left(vlookup(Z7,dayspo,19,0),1))) -> 1 | T7: =roundup(sum(L7:S7),0) -> 12 | U7: =T7-AF7 -> 6 | V7: 24/01/2025 | W7: IREPC24 | X7: 13 Hari | Y7: =value(left(X7,2)) -> 13 | Z7: 5100134016 | AA7: Normal | AC7: Non Agreement | AD7: 40 Hari | AE7: 6 Hari | AF7: =value(left(AE7,2)) -> 6 | AG7: 1 | AH7: 3939/E2D000/SR/SIPS/2024 | AI7: Rp 353.925.737 | AJ7: Rp 350.000.000 | AK7: Rp. 343.000.000 | AL7: 98 % | AM7: 1
A8: 2166575 | B8: Deisza Tarramif Thahull | C8: 2200099010 | D8: 10 | E8: Closed | F8: S41Z | G8: Jasa Penggantian Reformax 210/330 LDP | H8: B41 | I8: 45689 | J8: 45717 | K8: 45660 | L8: =Value(left(vlookup(Z8,dayspo,7,0),1)) -> 4 | M8: =roundup(Y8*'Days Sesion'!$S$2,0) -> 1 | N8: =roundup(Y8*'Days Sesion'!$S$3,0) -> 1 | O8: =roundup(Y8*'Days Sesion'!$S$5,0) -> 1 | P8: =Value(left(vlookup(Z8,dayspo,7,0),1)) -> 4 | Q8: =value(left(vlookup(Z8,dayspo,8,0),1)) -> 0 | R8: =roundup(Y8*'Days Sesion'!$S$8,0) -> 1 | S8: =(value(left(vlookup(Z8,dayspo,19,0),1))) -> 4 | T8: =roundup(sum(L8:S8),0) -> 16 | U8: =T8-AF8 -> 8 | V8: 17/01/2025 | W8: TA1BNH325 | X8: 10 Hari | Y8: =value(left(X8,2)) -> 10 | Z8: 5100133774 | AA8: Urgent | AC8: Non Agreement | AD8: 15 Hari | AE8: 8 Hari | AF8: =value(left(AE8,2)) -> 8 | AG8: 1 | AH8: 4029/E26000/SR/SIPS/2024 | AI8: Rp 2.200.000.000 | AJ8: Rp 2.150.000.000 | AK8: Rp. 2.140.000.000 | AL8: 99.53 % | AM8: 1
A9: 2166575 | B9: Deisza Tarramif Thahull | C9: 2200099103 | D9: 10 | E9: Closed | F9: S40Z | G9: PPM Bagging Machine 2B Jan-Jun 25 | H9: B40 | I9: 45839 | J9: 21/04/2025 | K9: 45667 | L9: =Value(left(vlookup(Z9,dayspo,7,0),1)) -> 2 | M9: =roundup(Y9*'Days Sesion'!$S$2,0) -> 1 | N9: =roundup(Y9*'Days Sesion'!$S$3,0) -> 1 | O9: =roundup(Y9*'Days Sesion'!$S$5,0) -> 2 | P9: =Value(left(vlookup(Z9,dayspo,7,0),1)) -> 2 | Q9: =value(left(vlookup(Z9,dayspo,8,0),1)) -> 5 | R9: =roundup(Y9*'Days Sesion'!$S$8,0) -> 1 | S9: =(value(left(vlookup(Z9,dayspo,19,0),1))) -> 4 | T9: =roundup(sum(L9:S9),0) -> 18 | U9: =T9-AF9 -> 7 | V9: 45689 | W9: IREPC25 | X9: 14 Hari | Y9: =value(left(X9,2)) -> 14 | Z9: 5100134053 | AA9: Normal | AC9: Non Agreement | AD9: 40 Hari | AE9: 11 Hari | AF9: =value(left(AE9,2)) -> 11 | AG9: 1 | AH9: 005/E2D000/SR/SIPS/2025 | AI9: Rp 523.171.523 | AJ9: Rp 523.171.523 | AK9: Rp. 516.000.000 | AL9: 98.63 % | AM9: 1
A10: 2166575 | B10: Deisza Tarramif Thahull | C10: 2200098397 | D10: 10 | E10: Closed | F10: S50J | G10: [SA2]Jasa Cleaning Economizer Tower 123 | H10: B50 | I10: 45334 | J10: 45901 | K10: 22/01/2025 | L10: =Value(left(vlookup(Z10,dayspo,7,0),1)) -> 1 | M10: =roundup(Y10*'Days Sesion'!$S$2,0) -> 1 | N10: =roundup(Y10*'Days Sesion'!$S$3,0) -> 1 | O10: =roundup(Y10*'Days Sesion'!$S$5,0) -> 1 | P10: =Value(left(vlookup(Z10,dayspo,7,0),1)) -> 1 | Q10: =value(left(vlookup(Z10,dayspo,8,0),1)) -> 4 | R10: =roundup(Y10*'Days Sesion'!$S$8,0) -> 1 | S10: =(value(left(vlookup(Z10,dayspo,19,0),1))) -> 2 | T10: =roundup(sum(L10:S10),0) -> 12 | U10: =T10-AF10 -> 5 | V10: 45692 | W10: TA3SA225 | X10: 7 Hari | Y10: =value(left(X10,2)) -> 7 | Z10: 5100134158 | AA10: TA | AC10: Non Agreement | AD10: 15 Hari | AE10: 7 Hari | AF10: =value(left(AE10,2)) -> 7 | AG10: 1 | AH10: 2985/E26000/SR/SIPS/2024 | AI10: Rp 390.105.183 | AJ10: Rp 390.105.183 | AK10: Rp. 380.000.000 | AL10: 97.41 % | AM10: 1
A11: 2166575 | B11: Deisza Tarramif Thahull | C11: 2200099214 | D11: 10 | E11: Closed | F11: S40Z | G11: Pemasangan CCTV System Unit ZA-2 | H11: B40 | I11: 45901 | J11: 22/01/2025 | K11: 30/01/2025 | L11: =Value(left(vlookup(Z11,dayspo,7,0),1)) -> 2 | M11: =roundup(Y11*'Days Sesion'!$S$2,0) -> 1 | N11: =roundup(Y11*'Days Sesion'!$S$3,0) -> 1 | O11: =roundup(Y11*'Days Sesion'!$S$5,0) -> 2 | P11: =Value(left(vlookup(Z11,dayspo,7,0),1)) -> 2 | Q11: =value(left(vlookup(Z11,dayspo,8,0),1)) -> 6 | R11: =roundup(Y11*'Days Sesion'!$S$8,0) -> 1 | S11: =(value(left(vlookup(Z11,dayspo,19,0),1))) -> 2 | T11: =roundup(sum(L11:S11),0) -> 17 | U11: =T11-AF11 -> 7 | V11: 28/02/2025 | W11: IREPC25 | X11: 21 Hari | Y11: =value(left(X11,2)) -> 21 | Z11: 5100135462 | AA11: Normal | AC11: Non Agreement | AD11: 40 Hari | AE11: 10 Hari | AF11: =value(left(AE11,2)) -> 10 | AG11: 1 | AH11: 100/E2D000/SR/SIPS/2025 | AI11: Rp 217.317.000 | AJ11: Rp 220.000.000 | AK11: Rp. 218.000.000 | AL11: 99.09 % | AM11: 1
A12: 2166575 | B12: Deisza Tarramif Thahull | C12: 2200099258 | D12: 10 | E12: Closed | F12: S50F | G12: Jasa Perbaikan Struktur Area 1A | H12: B50 | I12: 13/01/2025 | J12: 21/02/2025 | K12: 14/01/2025 | L12: =Value(left(vlookup(Z12,dayspo,7,0),1)) -> 0 | M12: =roundup(Y12*'Days Sesion'!$S$2,0) -> 1 | N12: =roundup(Y12*'Days Sesion'!$S$3,0) -> 1 | O12: =roundup(Y12*'Days Sesion'!$S$5,0) -> 1 | P12: =Value(left(vlookup(Z12,dayspo,7,0),1)) -> 0 | Q12: =value(left(vlookup(Z12,dayspo,8,0),1)) -> 4 | R12: =roundup(Y12*'Days Sesion'!$S$8,0) -> 1 | S12: =(value(left(vlookup(Z12,dayspo,19,0),1))) -> 1 | T12: =roundup(sum(L12:S12),0) -> 9 | U12: =T12-AF12 -> 4 | V12: 23/01/2025 | W12: IREPC25 | X12: 7 Hari | Y12: =value(left(X12,2)) -> 7 | Z12: 5100133962 | AA12: Normal | AC12: Non Agreement | AD12: 40 Hari | AE12: 5 Hari | AF12: =value(left(AE12,2)) -> 5 | AG12: 1 | AH12: 119/E2D000/SR/SIPS/2025 | AI12: Rp 403.636.638 | AJ12: Rp 403.636.638 | AK12: Rp. 395.000.000 | AL12: 97.86 % | AM12: 1
A13: 2166575 | B13: Deisza Tarramif Thahull | C13: 2200099259 | D13: 10 | E13: Closed | F13: S50F | G13: Perbaikan Struktur & Pipa Area Pabrik 1B | H13: B50 | I13: 13/01/2025 | J13: 20/03/2025 | K13: 14/01/2025 | L13: =Value(left(vlookup(Z13,dayspo,7,0),1)) -> 0 | M13: =roundup(Y13*'Days Sesion'!$S$2,0) -> 1 | N13: =roundup(Y13*'Days Sesion'!$S$3,0) -> 1 | O13: =roundup(Y13*'Days Sesion'!$S$5,0) -> 1 | P13: =Value(left(vlookup(Z13,dayspo,7,0),1)) -> 0 | Q13: =value(left(vlookup(Z13,dayspo,8,0),1)) -> 4 | R13: =roundup(Y13*'Days Sesion'!$S$8,0) -> 1 | S13: =(value(left(vlookup(Z13,dayspo,19,0),1))) -> 0 | T13: =roundup(sum(L13:S13),0) -> 8 | U13: =T13-AF13 -> 4 | V13: 23/01/2025 | W13: IREPC25 | X13: 7 Hari | Y13: =value(left(X13,2)) -> 7 | Z13: 5100133981 | AA13: Normal | AC13: Non Agreement | AD13: 40 Hari | AE13: 4 Hari | AF13: =value(left(AE13,2)) -> 4 | AG13: 1 | AH13: 163/E2D000/SR/SIPS/2025 | AI13: Rp 444.147.219 | AJ13: Rp 444.147.219 | AK13: Rp. 435.000.000 | AL13: 97.94 % | AM13: 1
A14: 2166575 | B14: Deisza Tarramif Thahull | C14: 2200099260 | D14: 10 | E14: Closed | F14: S50F | G14: Pembongkaran Stack T4201 Pabrik CR | H14: B50 | I14: 13/01/2025 | J14: 20/03/2025 | K14: 20/01/2025 | L14: =Value(left(vlookup(Z14,dayspo,7,0),1)) -> 0 | M14: =roundup(Y14*'Days Sesion'!$S$2,0) -> 1 | N14: =roundup(Y14*'Days Sesion'!$S$3,0) -> 1 | O14: =roundup(Y14*'Days Sesion'!$S$5,0) -> 1 | P14: =Value(left(vlookup(Z14,dayspo,7,0),1)) -> 0 | Q14: =value(left(vlookup(Z14,dayspo,8,0),1)) -> 5 | R14: =roundup(Y14*'Days Sesion'!$S$8,0) -> 1 | S14: =(value(left(vlookup(Z14,dayspo,19,0),1))) -> 0 | T14: =roundup(sum(L14:S14),0) -> 9 | U14: =T14-AF14 -> 4 | V14: 30/01/2025 | W14: IREPC25 | X14: 6 Hari | Y14: =value(left(X14,2)) -> 6 | Z14: 5100134084 | AA14: Normal | AC14: Non Agreement | AD14: 40 Hari | AE14: 5 Hari | AF14: =value(left(AE14,2)) -> 5 | AG14: 1 | AH14: 153/E2D000/SR/SIPS/2025 | AI14: Rp 240.095.808 | AJ14: Rp 240.095.808 | AK14: Rp. 235.000.000 | AL14: 97.88 % | AM14: 1
A15: 2166575 | B15: Deisza Tarramif Thahull | C15: 2200099382 | D15: 10 | E15: Closed | F15: S37Z | G15: Repair Rotor 104 JA 1A | H15: B37 | I15: 16/01/2025 | J15: 21/02/2025 | K15: 17/01/2025 | L15: =Value(left(vlookup(Z15,dayspo,7,0),1)) -> 0 | M15: =roundup(Y15*'Days Sesion'!$S$2,0) -> 1 | N15: =roundup(Y15*'Days Sesion'!$S$3,0) -> 1 | O15: =roundup(Y15*'Days Sesion'!$S$5,0) -> 3 | P15: =roundup(Y15*'Days Sesion'!$S$6,0) -> 6 | Q15: =roundup(Y15*'Days Sesion'!$S$7,0) -> 4 | R15: =roundup(Y15*'Days Sesion'!$S$8,0) -> 1 | S15: =roundup(Y15*'Days Sesion'!$S$9,0) -> 5 | T15: =roundup(sum(L15:S15),0) -> 21 | U15: =T15-AF15 -> -2 | V15: 25/02/2025 | W15: IREPC25 | X15: 25 Hari | Y15: =value(left(X15,2)) -> 25 | Z15: 5100135176 | AA15: Normal | AC15: Non Agreement | AD15: 40 Hari | AE15: 23 Hari | AF15: =value(left(AE15,2)) -> 23 | AG15: 1 | AH15: 075/E2D000/SR/SIPS/2025 | AI15: Rp 723.600.000 | AJ15: Rp 697.121.721 | AK15: Rp. 680.000.000 | AL15: 97.54 % | AM15: 1
A16: 2166575 | B16: Deisza Tarramif Thahull | C16: 2200099320 | D16: 10 | E16: Closed | F16: S41Z | G16: Fabrikasi Perforated Plate 105D 1B | H16: B41 | I16: 16/01/2025 | J16: 16/01/2025 | K16: 17/01/2025 | L16: 1 | M16: =roundup(Y16*'Days Sesion'!$S$2,0) -> 1 | N16: =roundup(Y16*'Days Sesion'!$S$3,0) -> 1 | O16: =roundup(Y16*'Days Sesion'!$S$5,0) -> 1 | P16: =roundup(Y16*'Days Sesion'!$S$6,0) -> 3 | Q16: =roundup(Y16*'Days Sesion'!$S$7,0) -> 2 | R16: =roundup(Y16*'Days Sesion'!$S$8,0) -> 1 | S16: =roundup(Y16*'Days Sesion'!$S$9,0) -> 2 | T16: =roundup(sum(L16:S16),0) -> 12 | U16: =T16-AF16 -> 2 | V16: 45693 | W16: IREPC25 | X16: 11 Hari | Y16: =value(left(X16,2)) -> 11 | Z16: 5100134248 | AA16: Normal | AC16: Non Agreement | AD16: 40 Hari | AE16: 10 Hari | AF16: =value(left(AE16,2)) -> 10 | AG16: 1 | AH16: 076/E2D000/SR/SIPS/2025 | AI16: Rp 272.550.000 | AJ16: Rp 271.790.975 | AK16: Rp. 268.000.000 | AL16: 98.61 % | AM16: 1
A17: 2166575 | B17: Deisza Tarramif Thahull | C17: 2200099482 | D17: 10 | E17: Closed | F17: S42Z | G17: Sewa Bucket Pemuatan TUKS Pelabuhan | H17: B42 | I17: 20/01/2025 | J17: 28/07/2025 | K17: 24/01/2025 | L17: =Value(left(vlookup(Z17,dayspo,7,0),1)) -> 0 | M17: =roundup(Y17*'Days Sesion'!$S$2,0) -> 1 | N17: =roundup(Y17*'Days Sesion'!$S$3,0) -> 1 | O17: =roundup(Y17*'Days Sesion'!$S$5,0) -> 3 | P17: =Value(left(vlookup(Z17,dayspo,7,0),1)) -> 0 | Q17: =value(left(vlookup(Z17,dayspo,8,0),1)) -> 3 | R17: =roundup(Y17*'Days Sesion'!$S$8,0) -> 1 | S17: =(value(left(vlookup(Z17,dayspo,19,0),1))) -> 2 | T17: =roundup(sum(L17:S17),0) -> 11 | U17: =T17-AF17 -> 6 | V17: 45722 | W17: LPL25 | X17: 27 Hari | Y17: =value(left(X17,2)) -> 27 | Z17: 4100004803 | AA17: Normal | AC17: Non Agreement | AD17: 40 Hari | AE17: 5 Hari | AF17: =value(left(AE17,2)) -> 5 | AG17: 1 | AH17: 164/E14000/SR/SIPS/2025 | AI17: Rp 712.500.000 | AJ17: Rp 712.500.000 | AK17: Rp. 712.250.000 | AL17: 99.96 % | AM17: 1
A18: 2166575 | B18: Deisza Tarramif Thahull | C18: 2200099516 | D18: 10 | E18: Closed | F18: S45E | G18: Jasa Uji Radiografi | H18: B45 | I18: 22/01/2025 | J18: 29/10/2026 | K18: 30/01/2025 | L18: =Value(left(vlookup(Z18,dayspo,7,0),1)) -> 1 | M18: =roundup(Y18*'Days Sesion'!$S$2,0) -> 1 | N18: =roundup(Y18*'Days Sesion'!$S$3,0) -> 1 | O18: =roundup(Y18*'Days Sesion'!$S$5,0) -> 4 | P18: =Value(left(vlookup(Z18,dayspo,7,0),1)) -> 1 | Q18: =value(left(vlookup(Z18,dayspo,8,0),1)) -> 1 | R18: =roundup(Y18*'Days Sesion'!$S$8,0) -> 2 | S18: =(value(left(vlookup(Z18,dayspo,19,0),1))) -> 2 | T18: =roundup(sum(L18:S18),0) -> 13 | U18: =T18-AF18 -> -3 | V18: 20/03/2025 | W18: ISTIK25 | X18: 35 Hari | Y18: =value(left(X18,2)) -> 35 | Z18: 4100004817 | AA18: Normal | AC18: Non Agreement | AD18: 40 Hari | AE18: 16 Hari | AF18: =value(left(AE18,2)) -> 16 | AG18: 1 | AH18: 257/E21000/SR/SIPS/2025 | AI18: Rp 978.191.000 | AJ18: Rp 978.191.000 | AK18: Rp. 791.440.000 | AL18: 80.91 % | AM18: 1
A19: 2166575 | B19: Deisza Tarramif Thahull | C19: 2200099686 | D19: 10 | E19: Closed | F19: S50Z | G19: Jasa Repair 20M 04.02 Bottom Slag Boiler UBB | H19: B50 | I19: 30/01/2025 | J19: 30/01/2025 | K19: 45691 | L19: =Value(left(vlookup(Z19,dayspo,7,0),1)) -> 0 | M19: =roundup(Y19*'Days Sesion'!$S$2,0) -> 1 | N19: =roundup(Y19*'Days Sesion'!$S$3,0) -> 1 | O19: =roundup(Y19*'Days Sesion'!$S$5,0) -> 1 | P19: =Value(left(vlookup(Z19,dayspo,7,0),1)) -> 0 | Q19: =value(left(vlookup(Z19,dayspo,8,0),1)) -> 3 | R19: =roundup(Y19*'Days Sesion'!$S$8,0) -> 1 | S19: =(value(left(vlookup(Z19,dayspo,19,0),1))) -> 3 | T19: =roundup(sum(L19:S19),0) -> 10 | U19: =T19-AF19 -> 4 | V19: 45700 | W19: IREPC25 | X19: 7 Hari | Y19: =value(left(X19,2)) -> 7 | Z19: 5100134541 | AA19: Normal | AC19: Non Agreement | AD19: 40 Hari | AE19: 6 Hari | AF19: =value(left(AE19,2)) -> 6 | AG19: 1 | AH19: 262/E2D000/SR/SIPS/2025 | AI19: Rp 191.057.780 | AJ19: Rp 191.057.780 | AK19: Rp. 187.000.000 | AL19: 97.88 % | AM19: 1
A20: 2166575 | B20: Deisza Tarramif Thahull | C20: 2200099771 | D20: 10 | E20: Closed | F20: S38B | G20: Jasa Injeksi Sealant Block Valve Header Steam 101 F Ammonia | H20: B38 | I20: 31/01/2025 | J20: 31/01/2025 | K20: 45693 | L20: =Value(left(vlookup(Z20,dayspo,7,0),1)) -> 0 | M20: =roundup(Y20*'Days Sesion'!$S$2,0) -> 1 | N20: =roundup(Y20*'Days Sesion'!$S$3,0) -> 1 | O20: =roundup(Y20*'Days Sesion'!$S$5,0) -> 1 | P20: =Value(left(vlookup(Z20,dayspo,7,0),1)) -> 0 | Q20: =value(left(vlookup(Z20,dayspo,8,0),1)) -> 4 | R20: =roundup(Y20*'Days Sesion'!$S$8,0) -> 1 | S20: =(value(left(vlookup(Z20,dayspo,19,0),1))) -> 1 | T20: =roundup(sum(L20:S20),0) -> 9 | U20: =T20-AF20 -> 4 | V20: 13/02/2025 | W20: IREPC25 | X20: 6 Hari | Y20: =value(left(X20,2)) -> 6 | Z20: 5100134577 | AA20: Normal | AC20: Non Agreement | AD20: 40 Hari | AE20: 5 Hari | AF20: =value(left(AE20,2)) -> 5 | AG20: 1 | AH20: 259/E2D000/SR/SIPS/2025 | AI20: Rp 46.750.000 | AJ20: Rp 46.750.000 | AK20: Rp. 45.000.000 | AL20: 96.26 % | AM20: 1
A21: 2166575 | B21: Deisza Tarramif Thahull | C21: 2200099425 | D21: 10 | E21: Closed | F21: S39Z | G21: Retrofit ACB TR01 & ACB PM2282C | H21: B39 | I21: 16/01/2025 | J21: 45718 | K21: 45695 | L21: =Value(left(vlookup(Z21,dayspo,7,0),1)) -> 0 | M21: =roundup(Y21*'Days Sesion'!$S$2,0) -> 1 | N21: =roundup(Y21*'Days Sesion'!$S$3,0) -> 1 | O21: =roundup(Y21*'Days Sesion'!$S$5,0) -> 2 | P21: =Value(left(vlookup(Z21,dayspo,7,0),1)) -> 0 | Q21: =value(left(vlookup(Z21,dayspo,8,0),1)) -> 5 | R21: =roundup(Y21*'Days Sesion'!$S$8,0) -> 1 | S21: =(value(left(vlookup(Z21,dayspo,19,0),1))) -> 7 | T21: =roundup(sum(L21:S21),0) -> 17 | U21: =T21-AF21 -> 5 | V21: 45719 | W21: TA1AUTL25 | X21: 16 Hari | Y21: =value(left(X21,2)) -> 16 | Z21: 5100135300 | AA21: TA | AC21: Non Agreement | AD21: 15 Hari | AE21: 12 Hari | AF21: =value(left(AE21,2)) -> 12 | AG21: 1 | AH21: 245/E26000/SR/SIPS/2025 | AI21: Rp 680.023.000 | AJ21: Rp 629.058.638 | AK21: Rp. 544.000.000 | AL21: 86.48 % | AM21: 1
A22: 2166575 | B22: Deisza Tarramif Thahull | C22: 2200099511 | D22: 10 | E22: Closed | F22: S37Z | G22: [SA2]Jasa Repair Generator | H22: B37 | I22: 20/01/2025 | J22: 45779 | K22: 45700 | L22: =Value(left(vlookup(Z22,dayspo,7,0),1)) -> 0 | M22: =roundup(Y22*'Days Sesion'!$S$2,0) -> 1 | N22: =roundup(Y22*'Days Sesion'!$S$3,0) -> 1 | O22: =roundup(Y22*'Days Sesion'!$S$5,0) -> 2 | P22: =Value(left(vlookup(Z22,dayspo,7,0),1)) -> 0 | Q22: =value(left(vlookup(Z22,dayspo,8,0),1)) -> 5 | R22: =roundup(Y22*'Days Sesion'!$S$8,0) -> 1 | S22: =(value(left(vlookup(Z22,dayspo,19,0),1))) -> 5 | T22: =roundup(sum(L22:S22),0) -> 15 | U22: =T22-AF22 -> 5 | V22: 45719 | W22: TA3SA225 | X22: 13 Hari | Y22: =value(left(X22,2)) -> 13 | Z22: 5100135296 | AA22: TA | AC22: Non Agreement | AD22: 15 Hari | AE22: 10 Hari | AF22: =value(left(AE22,2)) -> 10 | AG22: 1 | AH22: 381/E26000/SR/SIPS/2025 | AI22: Rp 863.982.260 | AJ22: Rp 857.464.230 | AK22: Rp. 839.860.000 | AL22: 97.95 % | AM22: 1
A23: 2166575 | B23: Deisza Tarramif Thahull | C23: 2200099967 | D23: 10 | E23: Closed | F23: S67Z | G23: Pengembangan APM | H23: B67 | I23: 45840 | J23: 45840 | K23: 18/02/2025 | L23: =Value(left(vlookup(Z23,dayspo,7,0),1)) -> 2 | M23: =roundup(Y23*'Days Sesion'!$S$2,0) -> 1 | N23: =roundup(Y23*'Days Sesion'!$S$3,0) -> 1 | O23: =roundup(Y23*'Days Sesion'!$S$5,0) -> 1 | P23: =Value(left(vlookup(Z23,dayspo,7,0),1)) -> 2 | Q23: =value(left(vlookup(Z23,dayspo,8,0),1)) -> 4 | R23: =roundup(Y23*'Days Sesion'!$S$8,0) -> 1 | S23: =(value(left(vlookup(Z23,dayspo,19,0),1))) -> 1 | T23: =roundup(sum(L23:S23),0) -> 13 | U23: =T23-AF23 -> 6 | V23: 27/02/2025 | W23: REL25 | X23: 7 Hari | Y23: =value(left(X23,2)) -> 7 | Z23: 5100135373 | AA23: Normal | AC23: Non Agreement | AD23: 40 Hari | AE23: 7 Hari | AF23: =value(left(AE23,2)) -> 7 | AG23: 1 | AH23: 142/E22000/SR/SIPS/2025 | AI23: Rp 102.944.160 | AJ23: Rp 102.944.160 | AK23: Rp. 100.782.344 | AL23: 97.9 % | AM23: 1
A24: 2166575 | B24: Deisza Tarramif Thahull | C24: 2200100292 | D24: 10 | E24: Closed | F24: S50F | G24: Jasa Penggantian Kabel Tray Phonska II & III | H24: B50 | I24: 15/02/2025 | J24: 18/03/2025 | K24: 20/02/2025 | L24: =Value(left(vlookup(Z24,dayspo,7,0),1)) -> 1 | M24: =roundup(Y24*'Days Sesion'!$S$2,0) -> 1 | N24: =roundup(Y24*'Days Sesion'!$S$3,0) -> 1 | O24: =roundup(Y24*'Days Sesion'!$S$5,0) -> 1 | P24: =Value(left(vlookup(Z24,dayspo,7,0),1)) -> 1 | Q24: =value(left(vlookup(Z24,dayspo,8,0),1)) -> 4 | R24: =roundup(Y24*'Days Sesion'!$S$8,0) -> 1 | S24: =(value(left(vlookup(Z24,dayspo,19,0),1))) -> 2 | T24: =roundup(sum(L24:S24),0) -> 12 | U24: =T24-AF24 -> 5 | V24: 45720 | W24: IREPC25 | X24: 8 Hari | Y24: =value(left(X24,2)) -> 8 | Z24: 5100135548 | AA24: Normal | AC24: Non Agreement | AD24: 40 Hari | AE24: 7 Hari | AF24: =value(left(AE24,2)) -> 7 | AG24: 1 | AH24: 478/E2D000/SR/SIPS/2025 | AI24: Rp 119.896.200 | AJ24: Rp 119.896.200 | AK24: Rp. 116.500.000 | AL24: 97.17 % | AM24: 1
A25: 2166575 | B25: Deisza Tarramif Thahull | C25: 2200100293 | D25: 10 | E25: Closed | F25: S41Z | G25: Pekerjaan Perbaikan MOV 2211 A B C D | H25: B41 | I25: 15/02/2025 | J25: 21/04/2025 | K25: 18/02/2025 | L25: =Value(left(vlookup(Z25,dayspo,7,0),1)) -> 3 | M25: =roundup(Y25*'Days Sesion'!$S$2,0) -> 1 | N25: =roundup(Y25*'Days Sesion'!$S$3,0) -> 1 | O25: =roundup(Y25*'Days Sesion'!$S$5,0) -> 2 | P25: =Value(left(vlookup(Z25,dayspo,7,0),1)) -> 3 | Q25: =value(left(vlookup(Z25,dayspo,8,0),1)) -> 8 | R25: =roundup(Y25*'Days Sesion'!$S$8,0) -> 1 | S25: =(value(left(vlookup(Z25,dayspo,19,0),1))) -> 1 | T25: =roundup(sum(L25:S25),0) -> 20 | U25: =T25-AF25 -> 8 | V25: 45723 | W25: IREPC25 | X25: 13 Hari | Y25: =value(left(X25,2)) -> 13 | Z25: 5100135702 | AA25: Normal | AC25: Non Agreement | AD25: 40 Hari | AE25: 12 Hari | AF25: =value(left(AE25,2)) -> 12 | AG25: 1 | AH25: 480/E2D000/SR/SIPS/2025 | AI25: Rp 188.500.000 | AJ25: Rp 188.500.000 | AK25: Rp. 170.000.000 | AL25: 90.19 % | AM25: 1
A26: 2166575 | B26: Deisza Tarramif Thahull | C26: 2200100274 | D26: 10 | E26: Closed | F26: S67Z | G26: Lisensi PHA Pro | H26: B67 | I26: 17/02/2025 | J26: 27/10/2025 | K26: 22/04/2025 | L26: =Value(left(vlookup(Z26,dayspo,7,0),1)) -> 0 | M26: =roundup(Y26*'Days Sesion'!$S$2,0) -> 1 | N26: =roundup(Y26*'Days Sesion'!$S$3,0) -> 1 | O26: =roundup(Y26*'Days Sesion'!$S$5,0) -> 2 | P26: =Value(left(vlookup(Z26,dayspo,7,0),1)) -> 0 | Q26: =value(left(vlookup(Z26,dayspo,8,0),1)) -> 2 | R26: =roundup(Y26*'Days Sesion'!$S$8,0) -> 1 | S26: =(value(left(vlookup(Z26,dayspo,19,0),1))) -> 3 | T26: =roundup(sum(L26:S26),0) -> 10 | U26: =T26-AF26 -> 5 | V26: 15/05/2025 | W26: TEKINFO25 | X26: 15 Hari | Y26: =value(left(X26,2)) -> 15 | Z26: 5100138434 | AA26: Normal | AC26: Non Agreement | AD26: 40 Hari | AE26: 5 Hari | AF26: =value(left(AE26,2)) -> 5 | AG26: 1 | AH26: 489/PBD200/SR/SIPS/2025 | AI26: Rp 257.196.000 | AJ26: Rp 197.500.000 | AK26: Rp. 193.500.000 | AL26: 97.97 % | AM26: 1
A27: 2166575 | B27: Deisza Tarramif Thahull | C27: 2200100274 | D27: 30 | E27: Closed | F27: S67Z | G27: Lisensi BowTieXP | H27: B67 | I27: 17/02/2025 | J27: 27/10/2025 | K27: 45816 | L27: =Value(left(vlookup(Z27,dayspo,7,0),1)) -> 2 | M27: =roundup(Y27*'Days Sesion'!$S$2,0) -> 1 | N27: =roundup(Y27*'Days Sesion'!$S$3,0) -> 1 | O27: =roundup(Y27*'Days Sesion'!$S$5,0) -> 3 | P27: =Value(left(vlookup(Z27,dayspo,7,0),1)) -> 2 | Q27: =value(left(vlookup(Z27,dayspo,8,0),1)) -> 5 | R27: =roundup(Y27*'Days Sesion'!$S$8,0) -> 2 | S27: =(value(left(vlookup(Z27,dayspo,19,0),1))) -> 1 | T27: =roundup(sum(L27:S27),0) -> 17 | U27: =T27-AF27 -> 9 | V27: 24/07/2025 | W27: TEKINFO25 | X27: 32 Hari | Y27: =value(left(X27,2)) -> 32 | Z27: 5100141320 | AA27: Normal | AC27: Non Agreement | AD27: 40 Hari | AE27: 8 Hari | AF27: =value(left(AE27,2)) -> 8 | AG27: 1 | AH27: - | AI27: Rp 0 | AJ27: Rp 84.790.000 | AK27: Rp. 84.000.000 | AL27: 99.07 % | AM27: 1
A28: 2166575 | B28: Deisza Tarramif Thahull | C28: 2200100349 | D28: 10 | E28: Closed | F28: S38A | G28: Jasa Laminasi Pipa 34 Inchi area KM 4+200 Jalur KAI Sememi Kandangan PA Gunung Sari | H28: B38 | I28: 18/02/2025 | J28: 18/02/2025 | K28: 21/02/2025 | L28: =Value(left(vlookup(Z28,dayspo,7,0),1)) -> 2 | M28: =roundup(Y28*'Days Sesion'!$S$2,0) -> 1 | N28: =roundup(Y28*'Days Sesion'!$S$3,0) -> 1 | O28: =roundup(Y28*'Days Sesion'!$S$5,0) -> 1 | P28: =Value(left(vlookup(Z28,dayspo,7,0),1)) -> 2 | Q28: =value(left(vlookup(Z28,dayspo,8,0),1)) -> 5 | R28: =roundup(Y28*'Days Sesion'!$S$8,0) -> 1 | S28: =(value(left(vlookup(Z28,dayspo,19,0),1))) -> 2 | T28: =roundup(sum(L28:S28),0) -> 15 | U28: =T28-AF28 -> 6 | V28: 45723 | W28: IREPC25 | X28: 10 Hari | Y28: =value(left(X28,2)) -> 10 | Z28: 5100135641 | AA28: Normal | AC28: Non Agreement | AD28: 40 Hari | AE28: 9 Hari | AF28: =value(left(AE28,2)) -> 9 | AG28: 1 | AH28: 472/E2D000/SR/SIPS/2025 | AI28: Rp 392.082.000 | AJ28: Rp 380.745.975 | AK28: Rp. 379.000.000 | AL28: 99.54 % | AM28: 1
A29: 2166575 | B29: Deisza Tarramif Thahull | C29: 2200100309 | D29: 10 | E29: Closed | F29: S39E | G29: Jasa Prefentive switchgear Phonska I | H29: B39 | I29: 19/02/2025 | J29: 45812 | K29: 26/02/2025 | L29: =Value(left(vlookup(Z29,dayspo,7,0),1)) -> 1 | M29: =roundup(Y29*'Days Sesion'!$S$2,0) -> 1 | N29: =roundup(Y29*'Days Sesion'!$S$3,0) -> 1 | O29: =roundup(Y29*'Days Sesion'!$S$5,0) -> 1 | P29: =Value(left(vlookup(Z29,dayspo,7,0),1)) -> 1 | Q29: =value(left(vlookup(Z29,dayspo,8,0),1)) -> 5 | R29: =roundup(Y29*'Days Sesion'!$S$8,0) -> 1 | S29: =(value(left(vlookup(Z29,dayspo,19,0),1))) -> 1 | T29: =roundup(sum(L29:S29),0) -> 12 | U29: =T29-AF29 -> 5 | V29: 45726 | W29: TA2PH125 | X29: 8 Hari | Y29: =value(left(X29,2)) -> 8 | Z29: 5100135739 | AA29: TA | AC29: Non Agreement | AD29: 15 Hari | AE29: 7 Hari | AF29: =value(left(AE29,2)) -> 7 | AG29: 1 | AH29: 577/E26000/SR/SIPS/2025 | AI29: Rp 117.585.900 | AJ29: Rp 109.108.000 | AK29: Rp. 102.000.000 | AL29: 93.49 % | AM29: 1
A30: 2166575 | B30: Deisza Tarramif Thahull | C30: 2200100637 | D30: 10 | E30: Closed | F30: S67C | G30: Pngmbangan Digital Twin & 3D Asset | H30: B67 | I30: 28/02/2025 | J30: 26/06/2025 | K30: 17/03/2025 | L30: =Value(left(vlookup(Z30,dayspo,7,0),1)) -> 4 | M30: =roundup(Y30*'Days Sesion'!$S$2,0) -> 1 | N30: =roundup(Y30*'Days Sesion'!$S$3,0) -> 1 | O30: =roundup(Y30*'Days Sesion'!$S$5,0) -> 1 | P30: =Value(left(vlookup(Z30,dayspo,7,0),1)) -> 4 | Q30: =value(left(vlookup(Z30,dayspo,8,0),1)) -> 3 | R30: =roundup(Y30*'Days Sesion'!$S$8,0) -> 1 | S30: =(value(left(vlookup(Z30,dayspo,19,0),1))) -> 0 | T30: =roundup(sum(L30:S30),0) -> 15 | U30: =T30-AF30 -> 8 | V30: 27/03/2025 | W30: TEKINFO25 | X30: 8 Hari | Y30: =value(left(X30,2)) -> 8 | Z30: 5100136776 | AA30: Normal | AC30: Non Agreement | AD30: 40 Hari | AE30: 7 Hari | AF30: =value(left(AE30,2)) -> 7 | AG30: 1 | AH30: 594/PBD200/SR/SIPS/2025 | AI30: Rp 351.021.800 | AJ30: Rp 351.021.800 | AK30: Rp. 350.000.000 | AL30: 99.71 % | AM30: 1
A31: 2166575 | B31: Deisza Tarramif Thahull | C31: 2200100969 | D31: 10 | E31: Closed | F31: S40Z | G31: Jasa PM Robot, Compressor & Dehumdifier | H31: B40 | I31: 45933 | J31: 27/10/2025 | K31: 45727 | L31: =Value(left(vlookup(Z31,dayspo,7,0),1)) -> 3 | M31: =roundup(Y31*'Days Sesion'!$S$2,0) -> 1 | N31: =roundup(Y31*'Days Sesion'!$S$3,0) -> 1 | O31: =roundup(Y31*'Days Sesion'!$S$5,0) -> 2 | P31: =Value(left(vlookup(Z31,dayspo,7,0),1)) -> 3 | Q31: =value(left(vlookup(Z31,dayspo,8,0),1)) -> 8 | R31: =roundup(Y31*'Days Sesion'!$S$8,0) -> 1 | S31: =(value(left(vlookup(Z31,dayspo,19,0),1))) -> 6 | T31: =roundup(sum(L31:S31),0) -> 25 | U31: =T31-AF31 -> 8 | V31: 15/04/2025 | W31: Gudang25 | X31: 18 Hari | Y31: =value(left(X31,2)) -> 18 | Z31: 5100136843 | AA31: Normal | AC31: Non Agreement | AD31: 40 Hari | AE31: 17 Hari | AF31: =value(left(AE31,2)) -> 17 | AG31: 1 | AH31: 618/E72000/SR/SIPS/2025 | AI31: Rp 621.780.000 | AJ31: Rp 546.424.020 | AK31: Rp. 540.000.000 | AL31: 98.82 % | AM31: 1
